<sdf version='1.6'>
  <world name='default'>
    <physics name='default_physics' default='0' type='ode'>
      <max_step_size>0.004</max_step_size>
      <real_time_factor>1</real_time_factor>
      <real_time_update_rate>250</real_time_update_rate>
    </physics>
    <light name='sun' type='directional'>
      <cast_shadows>1</cast_shadows>
      <pose frame=''>0 0 10 0 -0 0</pose>
      <diffuse>0.8 0.8 0.8 1</diffuse>
      <specular>0.2 0.2 0.2 1</specular>
      <attenuation>
        <range>1000</range>
        <constant>0.9</constant>
        <linear>0.01</linear>
        <quadratic>0.001</quadratic>
      </attenuation>
      <direction>-0.5 0.1 -0.9</direction>
    </light>
    <model name='ground_plane'>
      <static>1</static>
      <link name='link'>
        <collision name='collision'>
          <geometry>
            <plane>
              <normal>0 0 1</normal>
              <size>100 100</size>
            </plane>
          </geometry>
          <surface>
            <contact>
              <collide_bitmask>65535</collide_bitmask>
              <ode/>
            </contact>
            <friction>
              <ode>
                <mu>100</mu>
                <mu2>50</mu2>
              </ode>
              <torsional>
                <ode/>
              </torsional>
            </friction>
            <bounce/>
          </surface>
          <max_contacts>10</max_contacts>
        </collision>
        <visual name='visual'>
          <cast_shadows>0</cast_shadows>
          <geometry>
            <plane>
              <normal>0 0 1</normal>
              <size>100 100</size>
            </plane>
          </geometry>
          <material>
            <script>
              <uri>file://media/materials/scripts/gazebo.material</uri>
              <name>Gazebo/Grey</name>
            </script>
          </material>
        </visual>
        <self_collide>0</self_collide>
        <enable_wind>0</enable_wind>
        <kinematic>0</kinematic>
      </link>
    </model>
    <gravity>0 0 -9.8</gravity>
    <magnetic_field>6e-06 2.3e-05 -4.2e-05</magnetic_field>
    <atmosphere type='adiabatic'/>
    <scene>
      <ambient>0.4 0.4 0.4 1</ambient>
      <background>0.7 0.7 0.7 1</background>
      <shadows>1</shadows>
    </scene>
    <audio>
      <device>default</device>
    </audio>
    <wind/>
    <spherical_coordinates>
      <surface_model>EARTH_WGS84</surface_model>
      <latitude_deg>0</latitude_deg>
      <longitude_deg>0</longitude_deg>
      <elevation>0</elevation>
      <heading_deg>0</heading_deg>
    </spherical_coordinates>
    <model name='mbzirc_1'>
      <link name='base_link'>
        <pose frame=''>0 0 0 0 -0 0</pose>
        <inertial>
          <pose frame=''>0 0 -0.02475 0 -0 0</pose>
          <mass>6.18001</mass>
          <inertia>
            <ixx>0.354352</ixx>
            <ixy>0</ixy>
            <ixz>0</ixz>
            <iyy>0.354352</iyy>
            <iyz>5.16599e-07</iyz>
            <izz>0.468266</izz>
          </inertia>
        </inertial>
        <collision name='base_link_fixed_joint_lump__/camera_0_link_collision'>
          <pose frame=''>0 0.24 -0.24 3.14159 1.57079 3.14159</pose>
          <geometry>
            <box>
              <size>0.1 0.025 0.02</size>
            </box>
          </geometry>
          <surface>
            <contact>
              <ode/>
            </contact>
            <friction>
              <ode/>
              <torsional>
                <ode/>
              </torsional>
            </friction>
            <bounce/>
          </surface>
          <max_contacts>10</max_contacts>
        </collision>
        <collision name='base_link_inertia_collision_1'>
          <pose frame=''>0 0 0 0 -0 0</pose>
          <geometry>
            <cylinder>
              <length>0.6</length>
              <radius>0.4</radius>
            </cylinder>
          </geometry>
          <surface>
            <contact>
              <ode>
                <min_depth>0.001</min_depth>
                <max_vel>0</max_vel>
              </ode>
            </contact>
            <friction>
              <ode/>
              <torsional>
                <ode/>
              </torsional>
            </friction>
            <bounce/>
          </surface>
          <max_contacts>10</max_contacts>
        </collision>
        <collision name='base_link_fixed_joint_lump__base_collision_collision_2'>
          <pose frame=''>0 0 -0.4635 0 -0 0</pose>
          <geometry>
            <cylinder>
              <length>0.073</length>
              <radius>0.04</radius>
            </cylinder>
          </geometry>
          <max_contacts>10</max_contacts>
          <surface>
            <contact>
              <ode/>
            </contact>
            <bounce/>
            <friction>
              <torsional>
                <ode/>
              </torsional>
              <ode/>
            </friction>
          </surface>
        </collision>
        <visual name='base_link_fixed_joint_lump__/camera_0_link_visual'>
          <pose frame=''>0 0.24 -0.24 3.14159 1.57079 3.14159</pose>
          <geometry>
            <box>
              <size>0.1 0.025 0.02</size>
            </box>
          </geometry>
          <material>
            <script>
              <uri>__default__</uri>
              <name>__default__</name>
            </script>
          </material>
        </visual>
        <visual name='base_link_inertia_visual_1'>
          <pose frame=''>0 0 0 0 -0 0</pose>
          <geometry>
            <mesh>
              <scale>0.001 0.001 0.001</scale>
              <uri>model://robots_description/models/mbzirc/meshes/multirotor.dae</uri>
            </mesh>
          </geometry>
          <material>
            <script>
              <name>Gazebo/DarkGrey</name>
              <uri>file://media/materials/scripts/gazebo.material</uri>
            </script>
          </material>
        </visual>
        <visual name='base_link_fixed_joint_lump__base_visual_visual_2'>
          <pose frame=''>0 0 -0.5 0 -0 1.5707</pose>
          <geometry>
            <mesh>
              <scale>1 1 1</scale>
              <uri>model://ouster_description/meshes/os1_64.dae</uri>
            </mesh>
          </geometry>
        </visual>
        <velocity_decay/>
        <velocity_decay/>
        <sensor name='_camera_0' type='camera'>
          <update_rate>10</update_rate>
          <camera name='head'>
            <horizontal_fov>1.0708</horizontal_fov>
            <image>
              <width>800</width>
              <height>600</height>
              <format>R8G8B8</format>
            </image>
            <clip>
              <near>0.01</near>
              <far>100</far>
            </clip>
            <noise>
              <type>gaussian</type>
              <mean>0</mean>
              <stddev>0</stddev>
            </noise>
          </camera>
          <plugin name='_camera_0_controller' filename='libgazebo_ros_camera.so'>
            <robotNamespace/>
            <alwaysOn>1</alwaysOn>
            <updateRate>10</updateRate>
            <cameraName>camera_0</cameraName>
            <imageTopicName>image_raw</imageTopicName>
            <cameraInfoTopicName>camera_info</cameraInfoTopicName>
            <frameName>camera_0_link</frameName>
            <hackBaseline>0.0</hackBaseline>
            <distortionK1>0.0</distortionK1>
            <distortionK2>0.0</distortionK2>
            <distortionK3>0.0</distortionK3>
            <distortionT1>0.0</distortionT1>
            <distortionT2>0.0</distortionT2>
          </plugin>
          <pose frame=''>0 0.24 -0.24 3.14159 1.57079 3.14159</pose>
        </sensor>
        <velocity_decay/>
        <sensor name='os1_sensor-OS1-64' type='ray'>
          <visualize>0</visualize>
          <update_rate>10</update_rate>
          <ray>
            <scan>
              <horizontal>
                <samples>220</samples>
                <resolution>1</resolution>
                <min_angle>-3.14159</min_angle>
                <max_angle>3.14159</max_angle>
              </horizontal>
              <vertical>
                <samples>64</samples>
                <resolution>1</resolution>
                <min_angle>-0.26</min_angle>
                <max_angle>0.26</max_angle>
              </vertical>
            </scan>
            <range>
              <min>0.9</min>
              <max>75</max>
              <resolution>0.03</resolution>
            </range>
          </ray>
          <plugin name='gazebo_ros_laser_controller' filename='libgazebo_ros_ouster_laser.so'>
            <topicName>/os1_cloud_node/points</topicName>
            <frameName>os1_lidar</frameName>
            <min_range>0.9</min_range>
            <max_range>75.0</max_range>
            <gaussianNoise>0.008</gaussianNoise>
            <robotNamespace>/</robotNamespace>
          </plugin>
          <pose frame=''>0 0 -0.5 0 -0 0</pose>
        </sensor>
        <gravity>1</gravity>
        <velocity_decay/>
        <self_collide>0</self_collide>
        <enable_wind>0</enable_wind>
        <kinematic>0</kinematic>
      </link>
      <link name='/imu_link'>
        <pose frame=''>0 0 0 0 -0 0</pose>
        <inertial>
          <pose frame=''>0 0 0 0 -0 0</pose>
          <mass>0.015</mass>
          <inertia>
            <ixx>1e-05</ixx>
            <ixy>0</ixy>
            <ixz>0</ixz>
            <iyy>1e-05</iyy>
            <iyz>0</iyz>
            <izz>1e-05</izz>
          </inertia>
        </inertial>
        <self_collide>0</self_collide>
        <enable_wind>0</enable_wind>
        <kinematic>0</kinematic>
      </link>
      <joint name='/imu_joint' type='revolute'>
        <child>/imu_link</child>
        <parent>base_link</parent>
        <axis>
          <xyz>1 0 0</xyz>
          <limit>
            <lower>0</lower>
            <upper>0</upper>
            <effort>0</effort>
            <velocity>0</velocity>
          </limit>
          <dynamics>
            <spring_reference>0</spring_reference>
            <spring_stiffness>0</spring_stiffness>
          </dynamics>
          <use_parent_model_frame>1</use_parent_model_frame>
        </axis>
      </joint>
      <link name='magnetic_gripper'>
        <pose frame=''>0 0 -0.2 0 -0 0</pose>
        <inertial>
          <pose frame=''>0 0 0 0 -0 0</pose>
          <mass>0.015</mass>
          <inertia>
            <ixx>1e-05</ixx>
            <ixy>0</ixy>
            <ixz>0</ixz>
            <iyy>1e-05</iyy>
            <iyz>0</iyz>
            <izz>1e-05</izz>
          </inertia>
        </inertial>
        <visual name='magnetic_gripper_visual'>
          <pose frame=''>0 0 0 0 -0 0</pose>
          <geometry>
            <cylinder>
              <length>0.01</length>
              <radius>0.01</radius>
            </cylinder>
          </geometry>
        </visual>
        <self_collide>0</self_collide>
        <enable_wind>0</enable_wind>
        <kinematic>0</kinematic>
      </link>
      <joint name='base_to_gripper' type='revolute'>
        <child>magnetic_gripper</child>
        <parent>base_link</parent>
        <axis>
          <xyz>1 0 0</xyz>
          <limit>
            <lower>0</lower>
            <upper>0</upper>
            <effort>0</effort>
            <velocity>0</velocity>
          </limit>
          <dynamics>
            <spring_reference>0</spring_reference>
            <spring_stiffness>0</spring_stiffness>
          </dynamics>
          <use_parent_model_frame>1</use_parent_model_frame>
        </axis>
      </joint>
      <link name='rotor_0'>
        <pose frame=''>0 -0.39 0 0 -0 0</pose>
        <inertial>
          <pose frame=''>0 0 0 0 -0 0</pose>
          <mass>0.005</mass>
          <inertia>
            <ixx>9.75e-07</ixx>
            <ixy>0</ixy>
            <ixz>0</ixz>
            <iyy>0.000601704</iyy>
            <iyz>0</iyz>
            <izz>0.000602604</izz>
          </inertia>
        </inertial>
        <collision name='rotor_0_collision'>
          <pose frame=''>0 0 0 0 -0 0</pose>
          <geometry>
            <cylinder>
              <length>0.005</length>
              <radius>0.19</radius>
            </cylinder>
          </geometry>
          <surface>
            <contact>
              <ode/>
            </contact>
            <friction>
              <ode/>
              <torsional>
                <ode/>
              </torsional>
            </friction>
            <bounce/>
          </surface>
          <max_contacts>10</max_contacts>
        </collision>
        <visual name='rotor_0_visual'>
          <pose frame=''>0 0 0 0 -0 0</pose>
          <geometry>
            <mesh>
              <scale>0.001 0.001 0.001</scale>
              <uri>model://robots_description/models/mbzirc/meshes/prop_cw.dae</uri>
            </mesh>
          </geometry>
          <material>
            <script>
              <name>Gazebo/DarkGrey</name>
              <uri>file://media/materials/scripts/gazebo.material</uri>
            </script>
          </material>
        </visual>
        <gravity>1</gravity>
        <velocity_decay/>
        <self_collide>0</self_collide>
        <enable_wind>0</enable_wind>
        <kinematic>0</kinematic>
      </link>
      <joint name='rotor_0_joint' type='revolute'>
        <child>rotor_0</child>
        <parent>base_link</parent>
        <axis>
          <xyz>0 0 1</xyz>
          <limit>
            <lower>-1e+16</lower>
            <upper>1e+16</upper>
          </limit>
          <dynamics>
            <spring_reference>0</spring_reference>
            <spring_stiffness>0</spring_stiffness>
          </dynamics>
          <use_parent_model_frame>1</use_parent_model_frame>
        </axis>
      </joint>
      <link name='rotor_1'>
        <pose frame=''>0 0.39 0 0 -0 0</pose>
        <inertial>
          <pose frame=''>0 0 0 0 -0 0</pose>
          <mass>0.005</mass>
          <inertia>
            <ixx>9.75e-07</ixx>
            <ixy>0</ixy>
            <ixz>0</ixz>
            <iyy>0.000601704</iyy>
            <iyz>0</iyz>
            <izz>0.000602604</izz>
          </inertia>
        </inertial>
        <collision name='rotor_1_collision'>
          <pose frame=''>0 0 0 0 -0 0</pose>
          <geometry>
            <cylinder>
              <length>0.005</length>
              <radius>0.19</radius>
            </cylinder>
          </geometry>
          <surface>
            <contact>
              <ode/>
            </contact>
            <friction>
              <ode/>
              <torsional>
                <ode/>
              </torsional>
            </friction>
            <bounce/>
          </surface>
          <max_contacts>10</max_contacts>
        </collision>
        <visual name='rotor_1_visual'>
          <pose frame=''>0 0 0 0 -0 0</pose>
          <geometry>
            <mesh>
              <scale>0.001 0.001 0.001</scale>
              <uri>model://robots_description/models/mbzirc/meshes/prop_ccw.dae</uri>
            </mesh>
          </geometry>
          <material>
            <script>
              <name>Gazebo/DarkGrey</name>
              <uri>file://media/materials/scripts/gazebo.material</uri>
            </script>
          </material>
        </visual>
        <gravity>1</gravity>
        <velocity_decay/>
        <self_collide>0</self_collide>
        <enable_wind>0</enable_wind>
        <kinematic>0</kinematic>
      </link>
      <joint name='rotor_1_joint' type='revolute'>
        <child>rotor_1</child>
        <parent>base_link</parent>
        <axis>
          <xyz>0 0 1</xyz>
          <limit>
            <lower>-1e+16</lower>
            <upper>1e+16</upper>
          </limit>
          <dynamics>
            <spring_reference>0</spring_reference>
            <spring_stiffness>0</spring_stiffness>
          </dynamics>
          <use_parent_model_frame>1</use_parent_model_frame>
        </axis>
      </joint>
      <link name='rotor_2'>
        <pose frame=''>0.33775 0.195 0 0 -0 0</pose>
        <inertial>
          <pose frame=''>0 0 0 0 -0 0</pose>
          <mass>0.005</mass>
          <inertia>
            <ixx>9.75e-07</ixx>
            <ixy>0</ixy>
            <ixz>0</ixz>
            <iyy>0.000601704</iyy>
            <iyz>0</iyz>
            <izz>0.000602604</izz>
          </inertia>
        </inertial>
        <collision name='rotor_2_collision'>
          <pose frame=''>0 0 0 0 -0 0</pose>
          <geometry>
            <cylinder>
              <length>0.005</length>
              <radius>0.19</radius>
            </cylinder>
          </geometry>
          <surface>
            <contact>
              <ode/>
            </contact>
            <friction>
              <ode/>
              <torsional>
                <ode/>
              </torsional>
            </friction>
            <bounce/>
          </surface>
          <max_contacts>10</max_contacts>
        </collision>
        <visual name='rotor_2_visual'>
          <pose frame=''>0 0 0 0 -0 0</pose>
          <geometry>
            <mesh>
              <scale>0.001 0.001 0.001</scale>
              <uri>model://robots_description/models/mbzirc/meshes/prop_cw.dae</uri>
            </mesh>
          </geometry>
          <material>
            <script>
              <name>Gazebo/Orange</name>
              <uri>file://media/materials/scripts/gazebo.material</uri>
            </script>
          </material>
        </visual>
        <gravity>1</gravity>
        <velocity_decay/>
        <self_collide>0</self_collide>
        <enable_wind>0</enable_wind>
        <kinematic>0</kinematic>
      </link>
      <joint name='rotor_2_joint' type='revolute'>
        <child>rotor_2</child>
        <parent>base_link</parent>
        <axis>
          <xyz>0 0 1</xyz>
          <limit>
            <lower>-1e+16</lower>
            <upper>1e+16</upper>
          </limit>
          <dynamics>
            <spring_reference>0</spring_reference>
            <spring_stiffness>0</spring_stiffness>
          </dynamics>
          <use_parent_model_frame>1</use_parent_model_frame>
        </axis>
      </joint>
      <link name='rotor_3'>
        <pose frame=''>-0.33775 -0.195 0 0 -0 0</pose>
        <inertial>
          <pose frame=''>0 0 0 0 -0 0</pose>
          <mass>0.005</mass>
          <inertia>
            <ixx>9.75e-07</ixx>
            <ixy>0</ixy>
            <ixz>0</ixz>
            <iyy>0.000601704</iyy>
            <iyz>0</iyz>
            <izz>0.000602604</izz>
          </inertia>
        </inertial>
        <collision name='rotor_3_collision'>
          <pose frame=''>0 0 0 0 -0 0</pose>
          <geometry>
            <cylinder>
              <length>0.005</length>
              <radius>0.19</radius>
            </cylinder>
          </geometry>
          <surface>
            <contact>
              <ode/>
            </contact>
            <friction>
              <ode/>
              <torsional>
                <ode/>
              </torsional>
            </friction>
            <bounce/>
          </surface>
          <max_contacts>10</max_contacts>
        </collision>
        <visual name='rotor_3_visual'>
          <pose frame=''>0 0 0 0 -0 0</pose>
          <geometry>
            <mesh>
              <scale>0.001 0.001 0.001</scale>
              <uri>model://robots_description/models/mbzirc/meshes/prop_ccw.dae</uri>
            </mesh>
          </geometry>
          <material>
            <script>
              <name>Gazebo/DarkGrey</name>
              <uri>file://media/materials/scripts/gazebo.material</uri>
            </script>
          </material>
        </visual>
        <gravity>1</gravity>
        <velocity_decay/>
        <self_collide>0</self_collide>
        <enable_wind>0</enable_wind>
        <kinematic>0</kinematic>
      </link>
      <joint name='rotor_3_joint' type='revolute'>
        <child>rotor_3</child>
        <parent>base_link</parent>
        <axis>
          <xyz>0 0 1</xyz>
          <limit>
            <lower>-1e+16</lower>
            <upper>1e+16</upper>
          </limit>
          <dynamics>
            <spring_reference>0</spring_reference>
            <spring_stiffness>0</spring_stiffness>
          </dynamics>
          <use_parent_model_frame>1</use_parent_model_frame>
        </axis>
      </joint>
      <link name='rotor_4'>
        <pose frame=''>0.33775 -0.195 0 0 -0 0</pose>
        <inertial>
          <pose frame=''>0 0 0 0 -0 0</pose>
          <mass>0.005</mass>
          <inertia>
            <ixx>9.75e-07</ixx>
            <ixy>0</ixy>
            <ixz>0</ixz>
            <iyy>0.000601704</iyy>
            <iyz>0</iyz>
            <izz>0.000602604</izz>
          </inertia>
        </inertial>
        <collision name='rotor_4_collision'>
          <pose frame=''>0 0 0 0 -0 0</pose>
          <geometry>
            <cylinder>
              <length>0.005</length>
              <radius>0.19</radius>
            </cylinder>
          </geometry>
          <surface>
            <contact>
              <ode/>
            </contact>
            <friction>
              <ode/>
              <torsional>
                <ode/>
              </torsional>
            </friction>
            <bounce/>
          </surface>
          <max_contacts>10</max_contacts>
        </collision>
        <visual name='rotor_4_visual'>
          <pose frame=''>0 0 0 0 -0 0</pose>
          <geometry>
            <mesh>
              <scale>0.001 0.001 0.001</scale>
              <uri>model://robots_description/models/mbzirc/meshes/prop_ccw.dae</uri>
            </mesh>
          </geometry>
          <material>
            <script>
              <name>Gazebo/Orange</name>
              <uri>file://media/materials/scripts/gazebo.material</uri>
            </script>
          </material>
        </visual>
        <gravity>1</gravity>
        <velocity_decay/>
        <self_collide>0</self_collide>
        <enable_wind>0</enable_wind>
        <kinematic>0</kinematic>
      </link>
      <joint name='rotor_4_joint' type='revolute'>
        <child>rotor_4</child>
        <parent>base_link</parent>
        <axis>
          <xyz>0 0 1</xyz>
          <limit>
            <lower>-1e+16</lower>
            <upper>1e+16</upper>
          </limit>
          <dynamics>
            <spring_reference>0</spring_reference>
            <spring_stiffness>0</spring_stiffness>
          </dynamics>
          <use_parent_model_frame>1</use_parent_model_frame>
        </axis>
      </joint>
      <link name='rotor_5'>
        <pose frame=''>-0.33775 0.195 0 0 -0 0</pose>
        <inertial>
          <pose frame=''>0 0 0 0 -0 0</pose>
          <mass>0.005</mass>
          <inertia>
            <ixx>9.75e-07</ixx>
            <ixy>0</ixy>
            <ixz>0</ixz>
            <iyy>0.000601704</iyy>
            <iyz>0</iyz>
            <izz>0.000602604</izz>
          </inertia>
        </inertial>
        <collision name='rotor_5_collision'>
          <pose frame=''>0 0 0 0 -0 0</pose>
          <geometry>
            <cylinder>
              <length>0.005</length>
              <radius>0.19</radius>
            </cylinder>
          </geometry>
          <surface>
            <contact>
              <ode/>
            </contact>
            <friction>
              <ode/>
              <torsional>
                <ode/>
              </torsional>
            </friction>
            <bounce/>
          </surface>
          <max_contacts>10</max_contacts>
        </collision>
        <visual name='rotor_5_visual'>
          <pose frame=''>0 0 0 0 -0 0</pose>
          <geometry>
            <mesh>
              <scale>0.001 0.001 0.001</scale>
              <uri>model://robots_description/models/mbzirc/meshes/prop_cw.dae</uri>
            </mesh>
          </geometry>
          <material>
            <script>
              <name>Gazebo/DarkGrey</name>
              <uri>file://media/materials/scripts/gazebo.material</uri>
            </script>
          </material>
        </visual>
        <gravity>1</gravity>
        <velocity_decay/>
        <self_collide>0</self_collide>
        <enable_wind>0</enable_wind>
        <kinematic>0</kinematic>
      </link>
      <joint name='rotor_5_joint' type='revolute'>
        <child>rotor_5</child>
        <parent>base_link</parent>
        <axis>
          <xyz>0 0 1</xyz>
          <limit>
            <lower>-1e+16</lower>
            <upper>1e+16</upper>
          </limit>
          <dynamics>
            <spring_reference>0</spring_reference>
            <spring_stiffness>0</spring_stiffness>
          </dynamics>
          <use_parent_model_frame>1</use_parent_model_frame>
        </axis>
      </joint>
      <plugin name='imu_controller' filename='libhector_gazebo_ros_imu.so'>
        <robotNamespace>/</robotNamespace>
        <updateRate>100.0</updateRate>
        <topicName>/os1_cloud_node/imu</topicName>
        <accelDrift>0.005 0.005 0.005</accelDrift>
        <accelGaussianNoise>0.005 0.005 0.005</accelGaussianNoise>
        <rateDrift>0.005 0.005 0.005</rateDrift>
        <rateGaussianNoise>0.005 0.005 0.005</rateGaussianNoise>
        <headingDrift>0.005</headingDrift>
        <headingGaussianNoise>0.005</headingGaussianNoise>
        <bodyName>base_link</bodyName>
        <xyzOffset>-0.006253 0.011775 0.492355</xyzOffset>
        <rpyOffset>0 -0 0</rpyOffset>
      </plugin>
      <plugin name='rosbag' filename='libgazebo_multirotor_base_plugin.so'>
        <robotNamespace/>
        <linkName>base_link</linkName>
        <rotorVelocitySlowdownSim>10</rotorVelocitySlowdownSim>
      </plugin>
      <plugin name='right_motor_model' filename='libgazebo_motor_model.so'>
        <robotNamespace/>
        <jointName>rotor_0_joint</jointName>
        <linkName>rotor_0</linkName>
        <turningDirection>cw</turningDirection>
        <timeConstantUp>0.0125</timeConstantUp>
        <timeConstantDown>0.025</timeConstantDown>
        <maxRotVelocity>1100</maxRotVelocity>
        <motorConstant>2e-05</motorConstant>
        <momentConstant>0.12</momentConstant>
        <commandSubTopic>/gazebo/command/motor_speed</commandSubTopic>
        <motorNumber>0</motorNumber>
        <rotorDragCoefficient>0.000806428</rotorDragCoefficient>
        <rollingMomentCoefficient>1e-06</rollingMomentCoefficient>
        <motorSpeedPubTopic>/motor_speed/0</motorSpeedPubTopic>
        <rotorVelocitySlowdownSim>10</rotorVelocitySlowdownSim>
      </plugin>
      <plugin name='left_motor_model' filename='libgazebo_motor_model.so'>
        <robotNamespace/>
        <jointName>rotor_1_joint</jointName>
        <linkName>rotor_1</linkName>
        <turningDirection>ccw</turningDirection>
        <timeConstantUp>0.0125</timeConstantUp>
        <timeConstantDown>0.025</timeConstantDown>
        <maxRotVelocity>1100</maxRotVelocity>
        <motorConstant>2e-05</motorConstant>
        <momentConstant>0.12</momentConstant>
        <commandSubTopic>/gazebo/command/motor_speed</commandSubTopic>
        <motorNumber>1</motorNumber>
        <rotorDragCoefficient>0.000806428</rotorDragCoefficient>
        <rollingMomentCoefficient>1e-06</rollingMomentCoefficient>
        <motorSpeedPubTopic>/motor_speed/1</motorSpeedPubTopic>
        <rotorVelocitySlowdownSim>10</rotorVelocitySlowdownSim>
      </plugin>
      <plugin name='front_left_motor_model' filename='libgazebo_motor_model.so'>
        <robotNamespace/>
        <jointName>rotor_2_joint</jointName>
        <linkName>rotor_2</linkName>
        <turningDirection>cw</turningDirection>
        <timeConstantUp>0.0125</timeConstantUp>
        <timeConstantDown>0.025</timeConstantDown>
        <maxRotVelocity>1100</maxRotVelocity>
        <motorConstant>2e-05</motorConstant>
        <momentConstant>0.12</momentConstant>
        <commandSubTopic>/gazebo/command/motor_speed</commandSubTopic>
        <motorNumber>2</motorNumber>
        <rotorDragCoefficient>0.000806428</rotorDragCoefficient>
        <rollingMomentCoefficient>1e-06</rollingMomentCoefficient>
        <motorSpeedPubTopic>/motor_speed/2</motorSpeedPubTopic>
        <rotorVelocitySlowdownSim>10</rotorVelocitySlowdownSim>
      </plugin>
      <plugin name='back_right_motor_model' filename='libgazebo_motor_model.so'>
        <robotNamespace/>
        <jointName>rotor_3_joint</jointName>
        <linkName>rotor_3</linkName>
        <turningDirection>ccw</turningDirection>
        <timeConstantUp>0.0125</timeConstantUp>
        <timeConstantDown>0.025</timeConstantDown>
        <maxRotVelocity>1100</maxRotVelocity>
        <motorConstant>2e-05</motorConstant>
        <momentConstant>0.12</momentConstant>
        <commandSubTopic>/gazebo/command/motor_speed</commandSubTopic>
        <motorNumber>3</motorNumber>
        <rotorDragCoefficient>0.000806428</rotorDragCoefficient>
        <rollingMomentCoefficient>1e-06</rollingMomentCoefficient>
        <motorSpeedPubTopic>/motor_speed/3</motorSpeedPubTopic>
        <rotorVelocitySlowdownSim>10</rotorVelocitySlowdownSim>
      </plugin>
      <plugin name='front_right_motor_model' filename='libgazebo_motor_model.so'>
        <robotNamespace/>
        <jointName>rotor_4_joint</jointName>
        <linkName>rotor_4</linkName>
        <turningDirection>ccw</turningDirection>
        <timeConstantUp>0.0125</timeConstantUp>
        <timeConstantDown>0.025</timeConstantDown>
        <maxRotVelocity>1100</maxRotVelocity>
        <motorConstant>2e-05</motorConstant>
        <momentConstant>0.12</momentConstant>
        <commandSubTopic>/gazebo/command/motor_speed</commandSubTopic>
        <motorNumber>4</motorNumber>
        <rotorDragCoefficient>0.000806428</rotorDragCoefficient>
        <rollingMomentCoefficient>1e-06</rollingMomentCoefficient>
        <motorSpeedPubTopic>/motor_speed/4</motorSpeedPubTopic>
        <rotorVelocitySlowdownSim>10</rotorVelocitySlowdownSim>
      </plugin>
      <plugin name='back_left_motor_model' filename='libgazebo_motor_model.so'>
        <robotNamespace/>
        <jointName>rotor_5_joint</jointName>
        <linkName>rotor_5</linkName>
        <turningDirection>cw</turningDirection>
        <timeConstantUp>0.0125</timeConstantUp>
        <timeConstantDown>0.025</timeConstantDown>
        <maxRotVelocity>1100</maxRotVelocity>
        <motorConstant>2e-05</motorConstant>
        <momentConstant>0.12</momentConstant>
        <commandSubTopic>/gazebo/command/motor_speed</commandSubTopic>
        <motorNumber>5</motorNumber>
        <rotorDragCoefficient>0.000806428</rotorDragCoefficient>
        <rollingMomentCoefficient>1e-06</rollingMomentCoefficient>
        <motorSpeedPubTopic>/motor_speed/5</motorSpeedPubTopic>
        <rotorVelocitySlowdownSim>10</rotorVelocitySlowdownSim>
      </plugin>
      <plugin name='gps_plugin' filename='libgazebo_gps_plugin.so'>
        <robotNamespace/>
        <gpsNoise>1</gpsNoise>
      </plugin>
      <plugin name='magnetometer_plugin' filename='libgazebo_magnetometer_plugin.so'>
        <robotNamespace/>
        <pubRate>20</pubRate>
        <noiseDensity>0.0004</noiseDensity>
        <randomWalk>6.4e-06</randomWalk>
        <biasCorrelationTime>600</biasCorrelationTime>
        <magTopic>/mag</magTopic>
      </plugin>
      <plugin name='barometer_plugin' filename='libgazebo_barometer_plugin.so'>
        <robotNamespace/>
        <pubRate>10</pubRate>
        <baroTopic>/baro</baroTopic>
      </plugin>
      <plugin name='mavlink_interface' filename='libgazebo_mavlink_interface.so'>
        <robotNamespace/>
        <imuSubTopic>/imu</imuSubTopic>
        <gpsSubTopic>/gps</gpsSubTopic>
        <magSubTopic>/mag</magSubTopic>
        <baroSubTopic>/baro</baroSubTopic>
        <mavlink_addr>INADDR_ANY</mavlink_addr>
        <mavlink_udp_port>14560</mavlink_udp_port>
        <mavlink_tcp_port>4560</mavlink_tcp_port>
        <serialEnabled>0</serialEnabled>
        <serialDevice>/dev/ttyACM0</serialDevice>
        <baudRate>921600</baudRate>
        <qgc_addr>INADDR_ANY</qgc_addr>
        <qgc_udp_port>14550</qgc_udp_port>
        <sdk_addr>INADDR_ANY</sdk_addr>
        <sdk_udp_port>14540</sdk_udp_port>
        <hil_mode>0</hil_mode>
        <hil_state_level>0</hil_state_level>
        <vehicle_is_tailsitter>0</vehicle_is_tailsitter>
        <send_vision_estimation>1</send_vision_estimation>
        <send_odometry>0</send_odometry>
        <enable_lockstep>1</enable_lockstep>
        <use_tcp>1</use_tcp>
        <motorSpeedCommandPubTopic>/gazebo/command/motor_speed</motorSpeedCommandPubTopic>
        <control_channels>
          <channel name='rotor1'>
            <input_index>0</input_index>
            <input_offset>0</input_offset>
            <input_scaling>1000</input_scaling>
            <zero_position_disarmed>0</zero_position_disarmed>
            <zero_position_armed>100</zero_position_armed>
            <joint_control_type>velocity</joint_control_type>
          </channel>
          <channel name='rotor2'>
            <input_index>1</input_index>
            <input_offset>0</input_offset>
            <input_scaling>1000</input_scaling>
            <zero_position_disarmed>0</zero_position_disarmed>
            <zero_position_armed>100</zero_position_armed>
            <joint_control_type>velocity</joint_control_type>
          </channel>
          <channel name='rotor3'>
            <input_index>2</input_index>
            <input_offset>0</input_offset>
            <input_scaling>1000</input_scaling>
            <zero_position_disarmed>0</zero_position_disarmed>
            <zero_position_armed>100</zero_position_armed>
            <joint_control_type>velocity</joint_control_type>
          </channel>
          <channel name='rotor4'>
            <input_index>3</input_index>
            <input_offset>0</input_offset>
            <input_scaling>1000</input_scaling>
            <zero_position_disarmed>0</zero_position_disarmed>
            <zero_position_armed>100</zero_position_armed>
            <joint_control_type>velocity</joint_control_type>
          </channel>
          <channel name='rotor5'>
            <input_index>4</input_index>
            <input_offset>0</input_offset>
            <input_scaling>1000</input_scaling>
            <zero_position_disarmed>0</zero_position_disarmed>
            <zero_position_armed>100</zero_position_armed>
            <joint_control_type>velocity</joint_control_type>
          </channel>
          <channel name='rotor6'>
            <input_index>5</input_index>
            <input_offset>0</input_offset>
            <input_scaling>1000</input_scaling>
            <zero_position_disarmed>0</zero_position_disarmed>
            <zero_position_armed>100</zero_position_armed>
            <joint_control_type>velocity</joint_control_type>
          </channel>
          <channel name='rotor7'>
            <input_index>6</input_index>
            <input_offset>0</input_offset>
            <input_scaling>0.524</input_scaling>
            <zero_position_disarmed>0</zero_position_disarmed>
            <zero_position_armed>0</zero_position_armed>
            <joint_control_type>position</joint_control_type>
            <joint_name>zephyr_delta_wing::flap_right_joint</joint_name>
            <joint_control_pid>
              <p>10.0</p>
              <i>0</i>
              <d>0</d>
              <iMax>0</iMax>
              <iMin>0</iMin>
              <cmdMax>20</cmdMax>
              <cmdMin>-20</cmdMin>
            </joint_control_pid>
          </channel>
          <channel name='rotor8'>
            <input_index>7</input_index>
            <input_offset>0</input_offset>
            <input_scaling>0.524</input_scaling>
            <zero_position_disarmed>0</zero_position_disarmed>
            <zero_position_armed>0</zero_position_armed>
            <joint_control_type>position</joint_control_type>
          </channel>
        </control_channels>
      </plugin>
      <static>0</static>
      <plugin name='rotors_gazebo_imu_plugin' filename='libgazebo_imu_plugin.so'>
        <robotNamespace/>
        <linkName>/imu_link</linkName>
        <imuTopic>/imu</imuTopic>
        <gyroscopeNoiseDensity>0.0003394</gyroscopeNoiseDensity>
        <gyroscopeRandomWalk>3.8785e-05</gyroscopeRandomWalk>
        <gyroscopeBiasCorrelationTime>1000.0</gyroscopeBiasCorrelationTime>
        <gyroscopeTurnOnBiasSigma>0.0087</gyroscopeTurnOnBiasSigma>
        <accelerometerNoiseDensity>0.004</accelerometerNoiseDensity>
        <accelerometerRandomWalk>0.006</accelerometerRandomWalk>
        <accelerometerBiasCorrelationTime>300.0</accelerometerBiasCorrelationTime>
        <accelerometerTurnOnBiasSigma>0.196</accelerometerTurnOnBiasSigma>
      </plugin>
      <pose frame=''>0 0 0.1 0 -0 0</pose>
    </model>
    <model name='grey_wall'>
      <static>1</static>
      <link name='link'>
        <pose frame=''>0 0 1.4 0 -0 0</pose>
        <collision name='collision'>
          <geometry>
            <box>
              <size>7.5 0.2 2.8</size>
            </box>
          </geometry>
          <max_contacts>10</max_contacts>
          <surface>
            <contact>
              <ode/>
            </contact>
            <bounce/>
            <friction>
              <torsional>
                <ode/>
              </torsional>
              <ode/>
            </friction>
          </surface>
        </collision>
        <visual name='visual'>
          <cast_shadows>0</cast_shadows>
          <geometry>
            <box>
              <size>7.5 0.2 2.8</size>
            </box>
          </geometry>
          <material>
            <script>
              <uri>model://grey_wall/materials/scripts</uri>
              <uri>model://grey_wall/materials/textures</uri>
              <name>vrc/grey_wall</name>
            </script>
          </material>
        </visual>
        <self_collide>0</self_collide>
        <enable_wind>0</enable_wind>
        <kinematic>0</kinematic>
      </link>
      <pose frame=''>0.38843 -2.59849 0 0 -0 0</pose>
    </model>
    <model name='grey_wall_0'>
      <static>1</static>
      <link name='link'>
        <pose frame=''>0 0 1.4 0 -0 0</pose>
        <collision name='collision'>
          <geometry>
            <box>
              <size>7.5 0.2 2.8</size>
            </box>
          </geometry>
          <max_contacts>10</max_contacts>
          <surface>
            <contact>
              <ode/>
            </contact>
            <bounce/>
            <friction>
              <torsional>
                <ode/>
              </torsional>
              <ode/>
            </friction>
          </surface>
        </collision>
        <visual name='visual'>
          <cast_shadows>0</cast_shadows>
          <geometry>
            <box>
              <size>7.5 0.2 2.8</size>
            </box>
          </geometry>
          <material>
            <script>
              <uri>model://grey_wall/materials/scripts</uri>
              <uri>model://grey_wall/materials/textures</uri>
              <name>vrc/grey_wall</name>
            </script>
          </material>
        </visual>
        <self_collide>0</self_collide>
        <enable_wind>0</enable_wind>
        <kinematic>0</kinematic>
      </link>
      <pose frame=''>0.682592 1.45832 0 0 -0 0</pose>
    </model>
    <model name='grey_wall_1'>
      <static>1</static>
      <link name='link'>
        <pose frame=''>0 0 1.4 0 -0 0</pose>
        <collision name='collision'>
          <geometry>
            <box>
              <size>7.5 0.2 2.8</size>
            </box>
          </geometry>
          <max_contacts>10</max_contacts>
          <surface>
            <contact>
              <ode/>
            </contact>
            <bounce/>
            <friction>
              <torsional>
                <ode/>
              </torsional>
              <ode/>
            </friction>
          </surface>
        </collision>
        <visual name='visual'>
          <cast_shadows>0</cast_shadows>
          <geometry>
            <box>
              <size>7.5 0.2 2.8</size>
            </box>
          </geometry>
          <material>
            <script>
              <uri>model://grey_wall/materials/scripts</uri>
              <uri>model://grey_wall/materials/textures</uri>
              <name>vrc/grey_wall</name>
            </script>
          </material>
        </visual>
        <self_collide>0</self_collide>
        <enable_wind>0</enable_wind>
        <kinematic>0</kinematic>
      </link>
      <pose frame=''>7.88665 1.4723 0 0 -0 0</pose>
    </model>
    <model name='grey_wall_2'>
      <static>1</static>
      <link name='link'>
        <pose frame=''>0 0 1.4 0 -0 0</pose>
        <collision name='collision'>
          <geometry>
            <box>
              <size>7.5 0.2 2.8</size>
            </box>
          </geometry>
          <max_contacts>10</max_contacts>
          <surface>
            <contact>
              <ode/>
            </contact>
            <bounce/>
            <friction>
              <torsional>
                <ode/>
              </torsional>
              <ode/>
            </friction>
          </surface>
        </collision>
        <visual name='visual'>
          <cast_shadows>0</cast_shadows>
          <geometry>
            <box>
              <size>7.5 0.2 2.8</size>
            </box>
          </geometry>
          <material>
            <script>
              <uri>model://grey_wall/materials/scripts</uri>
              <uri>model://grey_wall/materials/textures</uri>
              <name>vrc/grey_wall</name>
            </script>
          </material>
        </visual>
        <self_collide>0</self_collide>
        <enable_wind>0</enable_wind>
        <kinematic>0</kinematic>
      </link>
      <pose frame=''>10.2613 -2.64251 0 0 -0 0</pose>
    </model>
    <model name='grey_wall_3'>
      <static>1</static>
      <link name='link'>
        <pose frame=''>0 0 1.4 0 -0 0</pose>
        <collision name='collision'>
          <geometry>
            <box>
              <size>7.5 0.2 2.8</size>
            </box>
          </geometry>
          <max_contacts>10</max_contacts>
          <surface>
            <contact>
              <ode/>
            </contact>
            <bounce/>
            <friction>
              <torsional>
                <ode/>
              </torsional>
              <ode/>
            </friction>
          </surface>
        </collision>
        <visual name='visual'>
          <cast_shadows>0</cast_shadows>
          <geometry>
            <box>
              <size>7.5 0.2 2.8</size>
            </box>
          </geometry>
          <material>
            <script>
              <uri>model://grey_wall/materials/scripts</uri>
              <uri>model://grey_wall/materials/textures</uri>
              <name>vrc/grey_wall</name>
            </script>
          </material>
        </visual>
        <self_collide>0</self_collide>
        <enable_wind>0</enable_wind>
        <kinematic>0</kinematic>
      </link>
      <pose frame=''>10.6675 -4.15302 0 0 -0 0</pose>
    </model>
    <model name='grey_wall_4'>
      <static>1</static>
      <link name='link'>
        <pose frame=''>0 0 1.4 0 -0 0</pose>
        <collision name='collision'>
          <geometry>
            <box>
              <size>7.5 0.2 2.8</size>
            </box>
          </geometry>
          <max_contacts>10</max_contacts>
          <surface>
            <contact>
              <ode/>
            </contact>
            <bounce/>
            <friction>
              <torsional>
                <ode/>
              </torsional>
              <ode/>
            </friction>
          </surface>
        </collision>
        <visual name='visual'>
          <cast_shadows>0</cast_shadows>
          <geometry>
            <box>
              <size>7.5 0.2 2.8</size>
            </box>
          </geometry>
          <material>
            <script>
              <uri>model://grey_wall/materials/scripts</uri>
              <uri>model://grey_wall/materials/textures</uri>
              <name>vrc/grey_wall</name>
            </script>
          </material>
        </visual>
        <self_collide>0</self_collide>
        <enable_wind>0</enable_wind>
        <kinematic>0</kinematic>
      </link>
      <pose frame=''>0.888458 -7.60571 0 0 -0 0</pose>
    </model>
    <model name='grey_wall_4_clone'>
      <static>1</static>
      <link name='link'>
        <pose frame=''>0 0 1.4 0 -0 0</pose>
        <collision name='collision'>
          <geometry>
            <box>
              <size>7.5 0.2 2.8</size>
            </box>
          </geometry>
          <max_contacts>10</max_contacts>
          <surface>
            <contact>
              <ode/>
            </contact>
            <bounce/>
            <friction>
              <torsional>
                <ode/>
              </torsional>
              <ode/>
            </friction>
          </surface>
        </collision>
        <visual name='visual'>
          <cast_shadows>0</cast_shadows>
          <geometry>
            <box>
              <size>7.5 0.2 2.8</size>
            </box>
          </geometry>
          <material>
            <script>
              <uri>model://grey_wall/materials/scripts</uri>
              <uri>model://grey_wall/materials/textures</uri>
              <name>vrc/grey_wall</name>
            </script>
          </material>
        </visual>
        <self_collide>0</self_collide>
        <enable_wind>0</enable_wind>
        <kinematic>0</kinematic>
      </link>
      <pose frame=''>1.17861 -10.3106 0 0 -0 0</pose>
    </model>
    <model name='grey_wall_4_clone_0'>
      <static>1</static>
      <link name='link'>
        <pose frame=''>0 0 1.4 0 -0 0</pose>
        <collision name='collision'>
          <geometry>
            <box>
              <size>7.5 0.2 2.8</size>
            </box>
          </geometry>
          <max_contacts>10</max_contacts>
          <surface>
            <contact>
              <ode/>
            </contact>
            <bounce/>
            <friction>
              <torsional>
                <ode/>
              </torsional>
              <ode/>
            </friction>
          </surface>
        </collision>
        <visual name='visual'>
          <cast_shadows>0</cast_shadows>
          <geometry>
            <box>
              <size>7.5 0.2 2.8</size>
            </box>
          </geometry>
          <material>
            <script>
              <uri>model://grey_wall/materials/scripts</uri>
              <uri>model://grey_wall/materials/textures</uri>
              <name>vrc/grey_wall</name>
            </script>
          </material>
        </visual>
        <self_collide>0</self_collide>
        <enable_wind>0</enable_wind>
        <kinematic>0</kinematic>
      </link>
      <pose frame=''>9.94467 -10.2538 0 0 -0 0</pose>
    </model>
    <model name='grey_wall_4_clone_1'>
      <static>1</static>
      <link name='link'>
        <pose frame=''>0 0 1.4 0 -0 0</pose>
        <collision name='collision'>
          <geometry>
            <box>
              <size>7.5 0.2 2.8</size>
            </box>
          </geometry>
          <max_contacts>10</max_contacts>
          <surface>
            <contact>
              <ode/>
            </contact>
            <bounce/>
            <friction>
              <torsional>
                <ode/>
              </torsional>
              <ode/>
            </friction>
          </surface>
        </collision>
        <visual name='visual'>
          <cast_shadows>0</cast_shadows>
          <geometry>
            <box>
              <size>7.5 0.2 2.8</size>
            </box>
          </geometry>
          <material>
            <script>
              <uri>model://grey_wall/materials/scripts</uri>
              <uri>model://grey_wall/materials/textures</uri>
              <name>vrc/grey_wall</name>
            </script>
          </material>
        </visual>
        <self_collide>0</self_collide>
        <enable_wind>0</enable_wind>
        <kinematic>0</kinematic>
      </link>
      <pose frame=''>-7.31222 -5.17668 0 0 -0 0</pose>
    </model>
    <model name='grey_wall_4_clone_1_clone'>
      <static>1</static>
      <link name='link'>
        <pose frame=''>0 0 1.4 0 -0 0</pose>
        <collision name='collision'>
          <geometry>
            <box>
              <size>7.5 0.2 2.8</size>
            </box>
          </geometry>
          <max_contacts>10</max_contacts>
          <surface>
            <contact>
              <ode/>
            </contact>
            <bounce/>
            <friction>
              <torsional>
                <ode/>
              </torsional>
              <ode/>
            </friction>
          </surface>
        </collision>
        <visual name='visual'>
          <cast_shadows>0</cast_shadows>
          <geometry>
            <box>
              <size>7.5 0.2 2.8</size>
            </box>
          </geometry>
          <material>
            <script>
              <uri>model://grey_wall/materials/scripts</uri>
              <uri>model://grey_wall/materials/textures</uri>
              <name>vrc/grey_wall</name>
            </script>
          </material>
        </visual>
        <self_collide>0</self_collide>
        <enable_wind>0</enable_wind>
        <kinematic>0</kinematic>
      </link>
      <pose frame=''>-5.34925 -8.77831 0 0 0 -1.54249</pose>
    </model>
    <state world_name='default'>
      <sim_time>672 532000000</sim_time>
      <real_time>680 192396285</real_time>
      <wall_time>1612525776 220371761</wall_time>
      <iterations>168133</iterations>
      <model name='grey_wall'>
        <pose frame=''>0.512991 -2.59849 0 0 -0 0</pose>
        <scale>1 1 1</scale>
        <link name='link'>
          <pose frame=''>0.512991 -2.59849 1.4 0 -0 0</pose>
          <velocity>0 0 0 0 -0 0</velocity>
          <acceleration>0 0 0 0 -0 0</acceleration>
          <wrench>0 0 0 0 -0 0</wrench>
        </link>
      </model>
      <model name='grey_wall_0'>
        <pose frame=''>0.682592 1.48671 0 0 -0 0</pose>
        <scale>1 1 1</scale>
        <link name='link'>
          <pose frame=''>0.682592 1.48671 1.4 0 -0 0</pose>
          <velocity>0 0 0 0 -0 0</velocity>
          <acceleration>0 0 0 0 -0 0</acceleration>
          <wrench>0 0 0 0 -0 0</wrench>
        </link>
      </model>
      <model name='grey_wall_1'>
        <pose frame=''>7.86812 1.48022 0 0 -0 0</pose>
        <scale>1 1 1</scale>
        <link name='link'>
          <pose frame=''>7.86812 1.48022 1.4 0 -0 0</pose>
          <velocity>0 0 0 0 -0 0</velocity>
          <acceleration>0 0 0 0 -0 0</acceleration>
          <wrench>0 0 0 0 -0 0</wrench>
        </link>
      </model>
      <model name='grey_wall_2'>
        <pose frame=''>4.42421 -3.79335 0 0 0 -1.54043</pose>
        <scale>1 1 1</scale>
        <link name='link'>
          <pose frame=''>4.42421 -3.79335 1.4 0 0 -1.54043</pose>
          <velocity>0 0 0 0 -0 0</velocity>
          <acceleration>0 0 0 0 -0 0</acceleration>
          <wrench>0 0 0 0 -0 0</wrench>
        </link>
      </model>
      <model name='grey_wall_3'>
        <pose frame=''>9.95521 -2.42838 0 0 -0 1.55469</pose>
        <scale>1 1 1</scale>
        <link name='link'>
          <pose frame=''>9.95521 -2.42838 1.4 0 -0 1.55469</pose>
          <velocity>0 0 0 0 -0 0</velocity>
          <acceleration>0 0 0 0 -0 0</acceleration>
          <wrench>0 0 0 0 -0 0</wrench>
        </link>
      </model>
      <model name='grey_wall_4'>
        <pose frame=''>0.888458 -7.60571 0 0 -0 0</pose>
        <scale>1 1 1</scale>
        <link name='link'>
          <pose frame=''>0.888458 -7.60571 1.4 0 -0 0</pose>
          <velocity>0 0 0 0 -0 0</velocity>
          <acceleration>0 0 0 0 -0 0</acceleration>
          <wrench>0 0 0 0 -0 0</wrench>
        </link>
      </model>
      <model name='grey_wall_4_clone'>
        <pose frame=''>1.17861 -10.3106 0 0 -0 0</pose>
        <scale>1 1 1</scale>
        <link name='link'>
          <pose frame=''>1.17861 -10.3106 1.4 0 -0 0</pose>
          <velocity>0 0 0 0 -0 0</velocity>
          <acceleration>0 0 0 0 -0 0</acceleration>
          <wrench>0 0 0 0 -0 0</wrench>
        </link>
      </model>
      <model name='grey_wall_4_clone_0'>
        <pose frame=''>7.6852 -8.47812 0 0 -0 0.698213</pose>
        <scale>1 1 1</scale>
        <link name='link'>
          <pose frame=''>7.6852 -8.47812 1.4 0 -0 0.698213</pose>
          <velocity>0 0 0 0 -0 0</velocity>
          <acceleration>0 0 0 0 -0 0</acceleration>
          <wrench>0 0 0 0 -0 0</wrench>
        </link>
      </model>
      <model name='grey_wall_4_clone_1'>
        <pose frame=''>-5.60473 0.245186 0 0 0 -1.54249</pose>
        <scale>1 1 1</scale>
        <link name='link'>
          <pose frame=''>-5.60473 0.245186 1.4 0 0 -1.54249</pose>
          <velocity>0 0 0 0 -0 0</velocity>
          <acceleration>0 0 0 0 -0 0</acceleration>
          <wrench>0 0 0 0 -0 0</wrench>
        </link>
      </model>
      <model name='grey_wall_4_clone_1_clone'>
        <pose frame=''>-5.3921 -7.26505 0 0 0 -1.54249</pose>
        <scale>1 1 1</scale>
        <link name='link'>
          <pose frame=''>-5.3921 -7.26505 1.4 0 0 -1.54249</pose>
          <velocity>0 0 0 0 -0 0</velocity>
          <acceleration>0 0 0 0 -0 0</acceleration>
          <wrench>0 0 0 0 -0 0</wrench>
        </link>
      </model>
      <model name='ground_plane'>
        <pose frame=''>0 0 0 0 -0 0</pose>
        <scale>1 1 1</scale>
        <link name='link'>
          <pose frame=''>0 0 0 0 -0 0</pose>
          <velocity>0 0 0 0 -0 0</velocity>
          <acceleration>0 0 0 0 -0 0</acceleration>
          <wrench>0 0 0 0 -0 0</wrench>
        </link>
      </model>
      <model name='mbzirc_1'>
        <pose frame=''>-0.001523 0.003347 0.500004 -2.1e-05 -7.1e-05 0.47925</pose>
        <scale>1 1 1</scale>
        <link name='/imu_link'>
          <pose frame=''>-0.001524 0.003348 0.500004 -1.9e-05 -7e-05 0.479251</pose>
          <velocity>-0.00154 0.00087 0.010128 -0.001715 -0.003224 0.000207</velocity>
          <acceleration>-0.002701 0.01137 9.60771 0.023237 0.006232 0.00129</acceleration>
          <wrench>-4.1e-05 0.000171 0.144116 0 -0 0</wrench>
        </link>
        <link name='base_link'>
          <pose frame=''>-0.001523 0.003347 0.500004 -2.1e-05 -7.1e-05 0.47925</pose>
          <velocity>-0.001578 0.000865 0.010131 -0.001726 -0.003154 0.000226</velocity>
          <acceleration>0.000247 5e-06 9.60774 0.001133 0.001002 -0.000244</acceleration>
          <wrench>0.001527 2.8e-05 59.3759 0 -0 0</wrench>
        </link>
        <link name='magnetic_gripper'>
          <pose frame=''>-0.00151 0.003351 0.300004 -1.9e-05 -7e-05 0.479251</pose>
          <velocity>-0.000895 0.000527 0.010128 -0.001715 -0.003224 0.000207</velocity>
          <acceleration>-0.003885 0.015887 9.60771 0.023249 0.006235 0.00129</acceleration>
          <wrench>-5.8e-05 0.000238 0.144116 0 -0 0</wrench>
        </link>
        <link name='rotor_0'>
          <pose frame=''>0.17831 -0.342715 0.500011 -0.000316 3e-05 1.81787</pose>
          <velocity>-0.001468 0.000907 0.011302 0.000178 -0.001159 2.5666</velocity>
          <acceleration>0.008178 0.00043 9.60876 -2.82788 -0.149729 3.13456</acceleration>
          <wrench>4.1e-05 2e-06 0.048044 0 -0 0</wrench>
        </link>
        <link name='rotor_1'>
          <pose frame=''>-0.181359 0.349411 0.499997 2.1e-05 1.8e-05 -1.51463</pose>
          <velocity>-0.001612 0.000833 0.008955 -0.002119 -0.007255 -2.56614</velocity>
          <acceleration>0.011559 0.002186 9.60534 -0.728824 0.796595 3.13062</acceleration>
          <wrench>5.8e-05 1.1e-05 0.048027 0 -0 0</wrench>
        </link>
        <link name='rotor_2'>
          <pose frame=''>0.208258 0.332121 0.500024 -0.000316 3e-05 1.81787</pose>
          <velocity>-0.001608 0.000914 0.010241 0.000178 -0.001158 2.5666</velocity>
          <acceleration>0.011453 0.000281 9.6117 -2.83715 -0.186536 3.13457</acceleration>
          <wrench>5.7e-05 1e-06 0.048059 0 -0 0</wrench>
        </link>
        <link name='rotor_3'>
          <pose frame=''>-0.211306 -0.325425 0.499984 2.1e-05 1.8e-05 -1.51463</pose>
          <velocity>-0.001472 0.000826 0.010016 -0.002119 -0.007261 -2.56614</velocity>
          <acceleration>0.008255 0.002317 9.60239 2.46298 1.45253 -0.011003</acceleration>
          <wrench>4.1e-05 1.2e-05 0.048012 0 -0 0</wrench>
        </link>
        <link name='rotor_4'>
          <pose frame=''>0.388092 -0.013942 0.500031 2.1e-05 1.8e-05 -1.51463</pose>
          <velocity>-0.001537 0.000951 0.011414 -0.002119 -0.007258 -2.56614</velocity>
          <acceleration>0.009752 -0.000595 9.61343 -0.699882 1.31036 3.1306</acceleration>
          <wrench>4.9e-05 -3e-06 0.048067 0 -0 0</wrench>
        </link>
        <link name='rotor_5'>
          <pose frame=''>-0.391141 0.020638 0.499977 -0.000315 3e-05 1.81787</pose>
          <velocity>-0.001544 0.000789 0.008842 0.000178 -0.001163 2.5666</velocity>
          <acceleration>0.009918 0.003196 9.60066 -2.66802 0.485334 3.13459</acceleration>
          <wrench>5e-05 1.6e-05 0.048003 0 -0 0</wrench>
        </link>
      </model>
      <light name='sun'>
        <pose frame=''>0 0 10 0 -0 0</pose>
      </light>
    </state>
    <gui fullscreen='0'>
      <camera name='user_camera'>
        <pose frame=''>-15.5718 0.364397 15.623 0 0.687643 -0.043806</pose>
        <view_controller>orbit</view_controller>
        <projection_type>perspective</projection_type>
      </camera>
    </gui>
  </world>
</sdf>
